Workbook

Sheet summary
A1: location | B1: (Multiple Items)
A3: Count | B3: Column Labels
A4: Row Labels | B4: 2000 | C4: 2005 | D4: 2006 | E4: 2007 | F4: 2008 | G4: 2009 | H4: 2010 | I4: 2011 | J4: 2012 | K4: 2013 | L4: 2014 | M4: 2015 | N4: 2016 | O4: 2018 | P4: 2019 | Q4: 2020 | R4: 2021 | S4: Grand Total
A5: ISO | B5: 5 | C5: 1 | E5: 3 | L5: 23 | M5: 5 | O5: 7 | P5: 9 | Q5: 1 | S5: 54
A6: adult | C6: 1 | E6: 3 | O6: 7 | S6: 11
A7: juvenile | B7: 5 | L7: 23 | M7: 5 | P7: 9 | Q7: 1 | S7: 43
A8: BCS | C8: 4 | D8: 37 | E8: 35 | F8: 6 | G8: 19 | H8: 29 | I8: 11 | J8: 80 | K8: 22 | L8: 19 | M8: 3 | N8: 1 | O8: 4 | P8: 2 | Q8: 1 | R8: 18 | S8: 291
A9: adult | C9: 4 | D9: 37 | E9: 35 | F9: 6 | G9: 19 | H9: 29 | I9: 11 | J9: 80 | K9: 22 | L9: 19 | M9: 3 | N9: 1 | O9: 4 | P9: 2 | Q9: 1 | R9: 18 | S9: 291
A10: Grand Total | B10: 5 | C10: 5 | D10: 37 | E10: 38 | F10: 6 | G10: 19 | H10: 29 | I10: 11 | J10: 80 | K10: 22 | L10: 42 | M10: 8 | N10: 1 | O10: 11 | P10: 11 | Q10: 2 | R10: 18 | S10: 345

Sheet sample_list
A1: lab_id | B1: location | C1: age_class | D1: year | E1: project_code | F1: site_id | G1: collect_date | H1: run | I1: fork_length | J1: petro_no | K1: don’t run | L1: notes | M1: assignment
A2: CNH00154 | B2: Coleman Hatchery | C2: juvenile | D2: 2000 | E2: ISO | F2: Coleman Hatchery | J2: CNHA1 | M2: =VLOOKUP(A2,assignments!A:Y,3,FALSE) -> #N/A
A3: CNH00185 | B3: Coleman Hatchery | C3: juvenile | D3: 2000 | E3: ISO | F3: Coleman Hatchery | J3: CNHA2 | M3: =VLOOKUP(A3,assignments!A:Y,3,FALSE) -> #N/A
A4: CNH00165 | B4: Coleman Hatchery | C4: juvenile | D4: 2000 | E4: ISO | F4: Coleman Hatchery | J4: CNHA3 | M4: =VLOOKUP(A4,assignments!A:Y,3,FALSE) -> #N/A
A5: CNH00265 | B5: Coleman Hatchery | C5: juvenile | D5: 2000 | E5: ISO | F5: Coleman Hatchery | J5: CNHA4 | M5: =VLOOKUP(A5,assignments!A:Y,3,FALSE) -> #N/A
A6: CNH00275 | B6: Coleman Hatchery | C6: juvenile | D6: 2000 | E6: ISO | F6: Coleman Hatchery | J6: CNHA5 | M6: =VLOOKUP(A6,assignments!A:Y,3,FALSE) -> #N/A
A7: AL040814-2 | B7: Coleman Hatchery | C7: juvenile | D7: 2014 | E7: ISO | F7: Coleman Hatchery | G7: 41737 | H7: fall | I7: 65 | J7: IJC15 | M7: =VLOOKUP(A7,assignments!A:Y,3,FALSE) -> #N/A
A8: YR19006 | B8: yuba river | C8: juvenile | D8: 2019 | E8: ISO | F8: Hallwood Blvd | G8: 43577 | H8: fall | I8: 49 | J8: DMDD11 | K8: x | V8: SC_06_50016E | W8: 2006 | X8: BAT
A9: YR19008 | B9: yuba river | C9: juvenile | D9: 2019 | E9: ISO | F9: Hallwood Blvd | G9: 43577 | H9: fall | I9: 43 | J9: DMDE01 | K9: x | V9: SC_06_50017E | W9: 2006 | X9: FEA
A10: YR19001 | B10: yuba river | C10: juvenile | D10: 2019 | E10: ISO | F10: Hallwood Blvd | G10: 43577 | H10: fall | I10: 62 | J10: DMDF12 | K10: x | V10: SC_06_50018E | W10: 2006 | X10: CNH
A11: YR19004 | B11: yuba river | C11: juvenile | D11: 2019 | E11: ISO | F11: Hallwood Blvd | G11: 43577 | H11: fall | I11: 47 | J11: DMDF22 | K11: x | V11: SC_06_50019E | W11: 2006 | X11: DEE
A12: YR19003 | B12: yuba river | C12: juvenile | D12: 2019 | E12: ISO | F12: Hallwood Blvd | G12: 43577 | H12: fall | I12: 47 | J12: DMDH01 | K12: x | V12: SC_06_50020E | W12: 2006 | X12: DEE
A13: YR19009 | B13: yuba river | C13: juvenile | D13: 2019 | E13: ISO | F13: Hallwood Blvd | G13: 43577 | H13: fall | I13: 42 | J13: DMDH20 | K13: x | V13: SC_06_50023E | W13: 2006 | X13: BAT
A14: YR19005 | B14: yuba river | C14: juvenile | D14: 2019 | E14: ISO | F14: Hallwood Blvd | G14: 43577 | H14: fall | I14: 51 | J14: DMDJ22 | K14: x | V14: SC_06_50024E | W14: 2006 | X14: BAT
A15: YR19007 | B15: yuba river | C15: juvenile | D15: 2019 | E15: ISO | F15: Hallwood Blvd | G15: 43577 | H15: fall | I15: 51 | J15: DMDL14 | K15: x | V15: SC_06_50025E | W15: 2006 | X15: BAT
A16: YR19010 | B16: yuba river | C16: juvenile | D16: 2019 | E16: ISO | F16: Hallwood Blvd | G16: 43577 | H16: fall | I16: 36 | J16: DMDL23 | K16: x | V16: SC_06_50026E | W16: 2006 | X16: BUT
A17: YR19002 | B17: yuba river | C17: juvenile | D17: 2019 | E17: ISO | F17: Hallwood Blvd | G17: 43577 | H17: fall | I17: 53 | J17: DMDO17 | K17: x | V17: SC_06_50027E | W17: 2006 | X17: CNH
A18: AL041514-2 | B18: Coleman Hatchery | C18: juvenile | D18: 2014 | E18: ISO | F18: Coleman Hatchery | G18: 41744 | H18: fall | I18: 70 | J18: IJC6 | M18: =VLOOKUP(A18,assignments!A:Y,3,FALSE) -> #N/A
A19: AL040814-1 | B19: Coleman Hatchery | C19: juvenile | D19: 2014 | E19: ISO | F19: Coleman Hatchery | G19: 41737 | H19: fall | I19: 73 | J19: IJC8 | M19: =VLOOKUP(A19,assignments!A:Y,3,FALSE) -> #N/A
A20: CNH2015-2 | B20: Coleman Hatchery | C20: juvenile | D20: 2015 | E20: ISO | F20: Coleman Hatchery | G20: 42192 | I20: 88 | J20: IJC1 | M20: =VLOOKUP(A20,assignments!A:Y,3,FALSE) -> #N/A
A21: CNH2015-4 | B21: Coleman Hatchery | C21: juvenile | D21: 2015 | E21: ISO | F21: Coleman Hatchery | G21: 42192 | I21: 95 | J21: IJC14 | M21: =VLOOKUP(A21,assignments!A:Y,3,FALSE) -> #N/A
A22: CNH2015-6 | B22: Coleman Hatchery | C22: juvenile | D22: 2015 | E22: ISO | F22: Coleman Hatchery | G22: 42192 | I22: 78 | J22: IJC19 | M22: =VLOOKUP(A22,assignments!A:Y,3,FALSE) -> #N/A
A23: EE18_31624 | B23: Coleman Hatchery | C23: adult | D23: 2018 | E23: ISO | F23: Coleman Hatchery | G23: 43393 | H23: fall | I23: 580 | J23: CNHA6 | M23: =VLOOKUP(A23,assignments!A:Y,3,FALSE) -> #N/A
A24: AL041514-1 | B24: Coleman Hatchery | C24: juvenile | D24: 2014 | E24: ISO | F24: Coleman Hatchery | G24: 41744 | H24: fall | I24: 68 | J24: IJD11 | K24: x | V24: SC_06_50034E | W24: 2006 | X24: SAC
A25: CNH2015-5 | B25: Coleman Hatchery | C25: juvenile | D25: 2015 | E25: ISO | F25: Coleman Hatchery | G25: 42192 | I25: 87 | J25: IJD12 | K25: x | V25: SC_06_50035E | W25: 2006 | X25: DEE
A26: AL040814-3 | B26: Coleman Hatchery | C26: juvenile | D26: 2014 | E26: ISO | F26: Coleman Hatchery | G26: 41737 | H26: fall | I26: 69 | J26: IJD16 | K26: x | V26: SC_06_50036E | W26: 2006 | X26: FEA
A27: CNH2015-7 | B27: Coleman Hatchery | C27: juvenile | D27: 2015 | E27: ISO | F27: Coleman Hatchery | G27: 42192 | I27: 95 | J27: IJD20 | K27: x | V27: SC_06_50037E | W27: 2006 | X27: BAT
A28: CNH19001 | B28: Coleman Hatchery | C28: juvenile | D28: 2019 | E28: ISO | F28: Coleman Hatchery | G28: 43586 | H28: fall | I28: 72 | J28: IJP01 | K28: x | V28: SC_06_50040E | W28: 2006 | X28: BAT
A29: CNH19003 | B29: Coleman Hatchery | C29: juvenile | D29: 2019 | E29: ISO | F29: Coleman Hatchery | G29: 43586 | H29: fall | I29: 65 | J29: IJP03 | K29: x | V29: SC_06_50042E | W29: 2006 | X29: DEE
A30: CNH19005 | B30: Coleman Hatchery | C30: juvenile | D30: 2019 | E30: ISO | F30: Coleman Hatchery | G30: 43586 | H30: fall | I30: 76 | J30: IJP04 | K30: x | V30: SC_06_50044E | W30: 2006 | X30: DEE
A31: CNH19006 | B31: Coleman Hatchery | C31: juvenile | D31: 2019 | E31: ISO | F31: Coleman Hatchery | G31: 43586 | H31: fall | I31: 81 | J31: IJP05 | K31: x | V31: SC_06_50045E | W31: 2006 | X31: BAT
A32: EE18_31420 | B32: Coleman Hatchery | C32: adult | D32: 2018 | E32: ISO | F32: Coleman Hatchery | G32: 43393 | H32: fall | I32: 550 | J32: TEAI1 | M32: =VLOOKUP(A32,assignments!A:Y,3,FALSE) -> #N/A
A33: EE18_31571 | B33: Coleman Hatchery | C33: adult | D33: 2018 | E33: ISO | F33: Coleman Hatchery | G33: 43393 | H33: fall | I33: 850 | J33: TEAI2 | M33: =VLOOKUP(A33,assignments!A:Y,3,FALSE) -> #N/A
A34: EE18_31620 | B34: Coleman Hatchery | C34: adult | D34: 2018 | E34: ISO | F34: Coleman Hatchery | G34: 43393 | H34: fall | I34: 590 | J34: TEAI3 | M34: =VLOOKUP(A34,assignments!A:Y,3,FALSE) -> #N/A
A35: EE18_31544 | B35: Coleman Hatchery | C35: adult | D35: 2018 | E35: ISO | F35: Coleman Hatchery | G35: 43393 | H35: fall | I35: 640 | J35: TEAI5 | M35: =VLOOKUP(A35,assignments!A:Y,3,FALSE) -> #N/A
A36: EE18_31613 | B36: Coleman Hatchery | C36: adult | D36: 2018 | E36: ISO | F36: Coleman Hatchery | G36: 43393 | H36: fall | I36: 650 | J36: TEAI6 | M36: =VLOOKUP(A36,assignments!A:Y,3,FALSE) -> #N/A
A37: CNH19007 | B37: Coleman Hatchery | C37: juvenile | D37: 2019 | E37: ISO | F37: Coleman Hatchery | G37: 43586 | H37: fall | I37: 85 | J37: IJP06 | M37: =VLOOKUP(A37,assignments!A:Y,3,FALSE) -> #N/A
A38: CNH19011 | B38: Coleman Hatchery | C38: juvenile | D38: 2019 | E38: ISO | F38: Coleman Hatchery | G38: 43586 | H38: fall | I38: 66 | J38: IJP07 | M38: =VLOOKUP(A38,assignments!A:Y,3,FALSE) -> #N/A
A39: CNH19012 | B39: Coleman Hatchery | C39: juvenile | D39: 2019 | E39: ISO | F39: Coleman Hatchery | G39: 43586 | H39: fall | I39: 77 | J39: IJP08 | M39: =VLOOKUP(A39,assignments!A:Y,3,FALSE) -> #N/A
A40: CNH19013 | B40: Coleman Hatchery | C40: juvenile | D40: 2019 | E40: ISO | F40: Coleman Hatchery | G40: 43586 | H40: fall | I40: 78 | J40: IJP09 | M40: =VLOOKUP(A40,assignments!A:Y,3,FALSE) -> #N/A
...

Sheet assignments
A1: lab_id | B1: survey_year | C1: assignment | D1: age | E1: age_f | F1: age_f_rev | G1: FL_mm | H1: sex | I1: adipose_fin | J1: outmigration_year | K1: WY | L1: phenotype_mig | M1: simplified_classification | N1: simplified_classification_g | O1: natal_exit | P1: fw_exit | Q1: non_natal_rearing_prop | R1: n_all | S1: nat_n | T1: nat_perc | U1: nat_label | V1: nat_n_g | W1: nat_label_g | X1: survey_year_n | Y1: survey_year_label
A2: SC_05_50007E | B2: 2005 | C2: DEE | D2: 3 | E2: 3 | F2: 3 | G2: 680 | H2: female | I2: present | J2: 2003 | K2: AN | L2: NA | M2: MILDEE | N2: MILDEE | O2: NA | P2: 0 | Q2: NA | R2: 275 | S2: 67 | T2: 0.24363636 | U2: MILDEE_x000D_ N = 67 | V2: 67 | W2: MILDEE_x000D_ N = 67 | X2: 4 | Y2: 2005_x000D_ N = 4
A3: SC_05_50015E | B3: 2005 | C3: CNH | D3: 3 | E3: 3 | F3: 3 | G3: 720 | H3: female | I3: present | J3: 2003 | K3: AN | L3: NA | M3: Hatchery-strays | N3: Strays | O3: NA | P3: 0 | Q3: NA | R3: 275 | S3: 79 | T3: 0.41090909 | U3: Hatchery-strays_x000D_ N = 79 | V3: 113 | W3: Strays_x000D_ N = 113 | X3: 4 | Y3: 2005_x000D_ N = 4
A4: SC_05_50017E | B4: 2005 | C4: DEE | D4: 3 | E4: 3 | F4: 3 | G4: NA | H4: unknown | I4: present | J4: 2003 | K4: AN | L4: NA | M4: MILDEE | N4: MILDEE | O4: NA | P4: 0 | Q4: NA | R4: 275 | S4: 67 | T4: 0.24363636 | U4: MILDEE_x000D_ N = 67 | V4: 67 | W4: MILDEE_x000D_ N = 67 | X4: 4 | Y4: 2005_x000D_ N = 4
A5: SC_05_50022E | B5: 2005 | C5: SAC | D5: 3 | E5: 3 | F5: 3 | G5: 685 | H5: female | I5: present | J5: 2003 | K5: AN | L5: NA | M5: Wild-strays | N5: Strays | O5: NA | P5: 0 | Q5: NA | R5: 275 | S5: 34 | T5: 0.41090909 | U5: Wild-strays_x000D_ N = 34 | V5: 113 | W5: Strays_x000D_ N = 113 | X5: 4 | Y5: 2005_x000D_ N = 4
A6: SC_06_50012E | B6: 2006 | C6: CNH | D6: 3 | E6: 3 | F6: 3 | G6: 765 | H6: female | I6: present | J6: 2004 | K6: BN | L6: NA | M6: Hatchery-strays | N6: Strays | O6: NA | P6: 0 | Q6: NA | R6: 275 | S6: 79 | T6: 0.41090909 | U6: Hatchery-strays_x000D_ N = 79 | V6: 113 | W6: Strays_x000D_ N = 113 | X6: 36 | Y6: 2006_x000D_ N = 36
A7: SC_06_50015E | B7: 2006 | C7: MIL | D7: 3 | E7: 3 | F7: 3 | G7: 675 | H7: female | I7: present | J7: 2004 | K7: BN | L7: NA | M7: MILDEE | N7: MILDEE | O7: NA | P7: 0 | Q7: NA | R7: 275 | S7: 67 | T7: 0.24363636 | U7: MILDEE_x000D_ N = 67 | V7: 67 | W7: MILDEE_x000D_ N = 67 | X7: 36 | Y7: 2006_x000D_ N = 36
A8: SC_06_50016E | B8: 2006 | C8: BAT | D8: 2 | E8: 2 | F8: 2 | G8: 640 | H8: female | I8: present | J8: 2005 | K8: AN | L8: Fry | M8: BAT | N8: BAT | O8: 304.65448 | P8: 449.02485 | Q8: 0.54 | R8: 275 | S8: 79 | T8: 0.28727273 | U8: BAT_x000D_ N = 79 | V8: 79 | W8: BAT_x000D_ N = 79 | X8: 36 | Y8: 2006_x000D_ N = 36
A9: SC_06_50017E | B9: 2006 | C9: FEA | D9: 3 | E9: 3 | F9: 3 | G9: 670 | H9: male | I9: present | J9: 2004 | K9: BN | L9: NA | M9: Wild-strays | N9: Strays | O9: NA | P9: 0 | Q9: NA | R9: 275 | S9: 34 | T9: 0.41090909 | U9: Wild-strays_x000D_ N = 34 | V9: 113 | W9: Strays_x000D_ N = 113 | X9: 36 | Y9: 2006_x000D_ N = 36
A10: SC_06_50018E | B10: 2006 | C10: CNH | D10: 2 | E10: 2 | F10: 2 | G10: 668 | H10: female | I10: present | J10: 2005 | K10: AN | L10: NA | M10: Hatchery-strays | N10: Strays | O10: NA | P10: 0 | Q10: NA | R10: 275 | S10: 79 | T10: 0.41090909 | U10: Hatchery-strays_x000D_ N = 79 | V10: 113 | W10: Strays_x000D_ N = 113 | X10: 36 | Y10: 2006_x000D_ N = 36
A11: SC_06_50019E | B11: 2006 | C11: DEE | D11: 3 | E11: 3 | F11: 3 | G11: NA | H11: female | I11: present | J11: 2004 | K11: BN | L11: NA | M11: MILDEE | N11: MILDEE | O11: NA | P11: 0 | Q11: NA | R11: 275 | S11: 67 | T11: 0.24363636 | U11: MILDEE_x000D_ N = 67 | V11: 67 | W11: MILDEE_x000D_ N = 67 | X11: 36 | Y11: 2006_x000D_ N = 36
A12: SC_06_50020E | B12: 2006 | C12: DEE | D12: 3 | E12: 3 | F12: 3 | G12: 710 | H12: female | I12: present | J12: 2004 | K12: BN | L12: NA | M12: MILDEE | N12: MILDEE | O12: NA | P12: 0 | Q12: NA | R12: 275 | S12: 67 | T12: 0.24363636 | U12: MILDEE_x000D_ N = 67 | V12: 67 | W12: MILDEE_x000D_ N = 67 | X12: 36 | Y12: 2006_x000D_ N = 36
A13: SC_06_50023E | B13: 2006 | C13: BAT | D13: 2 | E13: 2 | F13: 2 | G13: 680 | H13: male | I13: present | J13: 2005 | K13: AN | L13: Smolt | M13: BAT | N13: BAT | O13: 438.66654 | P13: 513.6423 | Q13: 0.27 | R13: 275 | S13: 79 | T13: 0.28727273 | U13: BAT_x000D_ N = 79 | V13: 79 | W13: BAT_x000D_ N = 79 | X13: 36 | Y13: 2006_x000D_ N = 36
A14: SC_06_50024E | B14: 2006 | C14: BAT | D14: 3 | E14: 3 | F14: 3 | G14: 725 | H14: female | I14: present | J14: 2004 | K14: BN | L14: Fry | M14: BAT | N14: BAT | O14: 385.71754 | P14: 477.43735 | Q14: 0.29 | R14: 275 | S14: 79 | T14: 0.28727273 | U14: BAT_x000D_ N = 79 | V14: 79 | W14: BAT_x000D_ N = 79 | X14: 36 | Y14: 2006_x000D_ N = 36
A15: SC_06_50025E | B15: 2006 | C15: BAT | D15: 2 | E15: 2 | F15: 2 | G15: 760 | H15: female | I15: present | J15: 2005 | K15: AN | L15: Smolt | M15: BAT | N15: BAT | O15: 504.12529 | P15: 593.52956 | Q15: 0.3 | R15: 275 | S15: 79 | T15: 0.28727273 | U15: BAT_x000D_ N = 79 | V15: 79 | W15: BAT_x000D_ N = 79 | X15: 36 | Y15: 2006_x000D_ N = 36
A16: SC_06_50026E | B16: 2006 | C16: BUT | D16: 3 | E16: 3 | F16: 3 | G16: 750 | H16: male | I16: present | J16: 2004 | K16: BN | L16: NA | M16: Wild-strays | N16: Strays | O16: NA | P16: 0 | Q16: NA | R16: 275 | S16: 34 | T16: 0.41090909 | U16: Wild-strays_x000D_ N = 34 | V16: 113 | W16: Strays_x000D_ N = 113 | X16: 36 | Y16: 2006_x000D_ N = 36
A17: SC_06_50027E | B17: 2006 | C17: CNH | D17: 3 | E17: 3 | F17: 3 | G17: 715 | H17: male | I17: present | J17: 2004 | K17: BN | L17: NA | M17: Hatchery-strays | N17: Strays | O17: NA | P17: 0 | Q17: NA | R17: 275 | S17: 79 | T17: 0.41090909 | U17: Hatchery-strays_x000D_ N = 79 | V17: 113 | W17: Strays_x000D_ N = 113 | X17: 36 | Y17: 2006_x000D_ N = 36
A18: SC_06_50028E | B18: 2006 | C18: BAT | D18: 3 | E18: 3 | F18: 3 | G18: 865 | H18: male | I18: present | J18: 2004 | K18: BN | L18: Smolt | M18: BAT | N18: BAT | O18: 497.03572 | P18: 594.06254 | Q18: 0.26 | R18: 275 | S18: 79 | T18: 0.28727273 | U18: BAT_x000D_ N = 79 | V18: 79 | W18: BAT_x000D_ N = 79 | X18: 36 | Y18: 2006_x000D_ N = 36
A19: SC_06_50029E | B19: 2006 | C19: MIL | D19: 4 | E19: 4 | F19: 4 | G19: 800 | H19: female | I19: present | J19: 2003 | K19: AN | L19: NA | M19: MILDEE | N19: MILDEE | O19: NA | P19: 0 | Q19: NA | R19: 275 | S19: 67 | T19: 0.24363636 | U19: MILDEE_x000D_ N = 67 | V19: 67 | W19: MILDEE_x000D_ N = 67 | X19: 36 | Y19: 2006_x000D_ N = 36
A20: SC_06_50030E | B20: 2006 | C20: BAT | D20: 2 | E20: 2 | F20: 2 | G20: 710 | H20: female | I20: present | J20: 2005 | K20: AN | L20: Smolt | M20: BAT | N20: BAT | O20: 494.81722 | P20: 576.00659 | Q20: 0.23 | R20: 275 | S20: 79 | T20: 0.28727273 | U20: BAT_x000D_ N = 79 | V20: 79 | W20: BAT_x000D_ N = 79 | X20: 36 | Y20: 2006_x000D_ N = 36
A21: SC_06_50031E | B21: 2006 | C21: Unknown | D21: 3 | E21: 3 | F21: 3 | G21: 710 | H21: female | I21: present | J21: 2004 | K21: BN | L21: NA | M21: Unknown | N21: Unknown | O21: NA | P21: 0 | Q21: NA | R21: 275 | S21: 16 | T21: 0.058181818 | U21: Unknown_x000D_ N = 16 | V21: 16 | W21: Unknown_x000D_ N = 16 | X21: 36 | Y21: 2006_x000D_ N = 36
A22: SC_06_50032E | B22: 2006 | C22: BAT | D22: 2 | E22: 2 | F22: 2 | G22: 660 | H22: female | I22: present | J22: 2005 | K22: AN | L22: Smolt | M22: BAT | N22: BAT | O22: 479.849 | P22: 568.72174 | Q22: 0.25 | R22: 275 | S22: 79 | T22: 0.28727273 | U22: BAT_x000D_ N = 79 | V22: 79 | W22: BAT_x000D_ N = 79 | X22: 36 | Y22: 2006_x000D_ N = 36
A23: SC_06_50033E | B23: 2006 | C23: Unknown | D23: 3 | E23: 3 | F23: 3 | G23: 740 | H23: female | I23: present | J23: 2004 | K23: BN | L23: NA | M23: Unknown | N23: Unknown | O23: NA | P23: 0 | Q23: NA | R23: 275 | S23: 16 | T23: 0.058181818 | U23: Unknown_x000D_ N = 16 | V23: 16 | W23: Unknown_x000D_ N = 16 | X23: 36 | Y23: 2006_x000D_ N = 36
A24: SC_06_50034E | B24: 2006 | C24: SAC | D24: 3 | E24: 3 | F24: 3 | G24: 670 | H24: unknown | I24: present | J24: 2004 | K24: BN | L24: NA | M24: Wild-strays | N24: Strays | O24: NA | P24: 0 | Q24: NA | R24: 275 | S24: 34 | T24: 0.41090909 | U24: Wild-strays_x000D_ N = 34 | V24: 113 | W24: Strays_x000D_ N = 113 | X24: 36 | Y24: 2006_x000D_ N = 36
A25: SC_06_50035E | B25: 2006 | C25: DEE | D25: NA | E25: NA | F25: NA | G25: 745 | H25: female | I25: present | J25: NA | K25: NA | L25: NA | M25: MILDEE | N25: MILDEE | O25: NA | P25: 0 | Q25: NA | R25: 275 | S25: 67 | T25: 0.24363636 | U25: MILDEE_x000D_ N = 67 | V25: 67 | W25: MILDEE_x000D_ N = 67 | X25: 36 | Y25: 2006_x000D_ N = 36
A26: SC_06_50036E | B26: 2006 | C26: FEA | D26: 4 | E26: 4 | F26: 4 | G26: 830 | H26: male | I26: present | J26: 2003 | K26: AN | L26: NA | M26: Wild-strays | N26: Strays | O26: NA | P26: 0 | Q26: NA | R26: 275 | S26: 34 | T26: 0.41090909 | U26: Wild-strays_x000D_ N = 34 | V26: 113 | W26: Strays_x000D_ N = 113 | X26: 36 | Y26: 2006_x000D_ N = 36
A27: SC_06_50037E | B27: 2006 | C27: BAT | D27: 3 | E27: 3 | F27: 3 | G27: NA | H27: unknown | I27: present | J27: 2004 | K27: BN | L27: Smolt | M27: BAT | N27: BAT | O27: 470.67618 | P27: 560.0763 | Q27: 0.26 | R27: 275 | S27: 79 | T27: 0.28727273 | U27: BAT_x000D_ N = 79 | V27: 79 | W27: BAT_x000D_ N = 79 | X27: 36 | Y27: 2006_x000D_ N = 36
A28: SC_06_50040E | B28: 2006 | C28: BAT | D28: 2 | E28: 2 | F28: 2 | G28: 710 | H28: male | I28: present | J28: 2005 | K28: AN | L28: Fry | M28: BAT | N28: BAT | O28: 261.7692 | P28: 388.1202 | Q28: 0.47 | R28: 275 | S28: 79 | T28: 0.28727273 | U28: BAT_x000D_ N = 79 | V28: 79 | W28: BAT_x000D_ N = 79 | X28: 36 | Y28: 2006_x000D_ N = 36
A29: SC_06_50042E | B29: 2006 | C29: DEE | D29: 3 | E29: 3 | F29: 3 | G29: 725 | H29: female | I29: present | J29: 2004 | K29: BN | L29: NA | M29: MILDEE | N29: MILDEE | O29: NA | P29: 0 | Q29: NA | R29: 275 | S29: 67 | T29: 0.24363636 | U29: MILDEE_x000D_ N = 67 | V29: 67 | W29: MILDEE_x000D_ N = 67 | X29: 36 | Y29: 2006_x000D_ N = 36
A30: SC_06_50044E | B30: 2006 | C30: DEE | D30: 3 | E30: 3 | F30: 3 | G30: 765 | H30: female | I30: present | J30: 2004 | K30: BN | L30: NA | M30: MILDEE | N30: MILDEE | O30: NA | P30: 0 | Q30: NA | R30: 275 | S30: 67 | T30: 0.24363636 | U30: MILDEE_x000D_ N = 67 | V30: 67 | W30: MILDEE_x000D_ N = 67 | X30: 36 | Y30: 2006_x000D_ N = 36
A31: SC_06_50045E | B31: 2006 | C31: BAT | D31: 3 | E31: 3 | F31: 3 | G31: 780 | H31: female | I31: present | J31: 2004 | K31: BN | L31: Fry | M31: BAT | N31: BAT | O31: 393.66804 | P31: 502.14381 | Q31: 0.36 | R31: 275 | S31: 79 | T31: 0.28727273 | U31: BAT_x000D_ N = 79 | V31: 79 | W31: BAT_x000D_ N = 79 | X31: 36 | Y31: 2006_x000D_ N = 36
A32: SC_06_50046E | B32: 2006 | C32: BAT | D32: 3 | E32: 3 | F32: 3 | G32: 795 | H32: male | I32: present | J32: 2004 | K32: BN | L32: Fry | M32: BAT | N32: BAT | O32: 362.66523 | P32: 464.27072 | Q32: 0.42 | R32: 275 | S32: 79 | T32: 0.28727273 | U32: BAT_x000D_ N = 79 | V32: 79 | W32: BAT_x000D_ N = 79 | X32: 36 | Y32: 2006_x000D_ N = 36
A33: SC_06_50047E | B33: 2006 | C33: BAT | D33: 4 | E33: 4 | F33: 4 | G33: 790 | H33: female | I33: present | J33: 2003 | K33: AN | L33: Smolt | M33: BAT | N33: BAT | O33: 566.98364 | P33: 660.93897 | Q33: 0.28 | R33: 275 | S33: 79 | T33: 0.28727273 | U33: BAT_x000D_ N = 79 | V33: 79 | W33: BAT_x000D_ N = 79 | X33: 36 | Y33: 2006_x000D_ N = 36
A34: SC_06_50048E | B34: 2006 | C34: MIL | D34: 3 | E34: 3 | F34: 3 | G34: 755 | H34: female | I34: present | J34: 2004 | K34: BN | L34: NA | M34: MILDEE | N34: MILDEE | O34: NA | P34: 0 | Q34: NA | R34: 275 | S34: 67 | T34: 0.24363636 | U34: MILDEE_x000D_ N = 67 | V34: 67 | W34: MILDEE_x000D_ N = 67 | X34: 36 | Y34: 2006_x000D_ N = 36
A35: SC_06_50051E | B35: 2006 | C35: MIL | D35: 3 | E35: 3 | F35: 3 | G35: 700 | H35: female | I35: present | J35: 2004 | K35: BN | L35: NA | M35: MILDEE | N35: MILDEE | O35: NA | P35: 0 | Q35: NA | R35: 275 | S35: 67 | T35: 0.24363636 | U35: MILDEE_x000D_ N = 67 | V35: 67 | W35: MILDEE_x000D_ N = 67 | X35: 36 | Y35: 2006_x000D_ N = 36
A36: SC_06_50052E | B36: 2006 | C36: BAT | D36: 3 | E36: 3 | F36: 3 | G36: 835 | H36: male | I36: present | J36: 2004 | K36: BN | L36: Smolt | M36: BAT | N36: BAT | O36: 566.2578 | P36: 670.19708 | Q36: 0.29 | R36: 275 | S36: 79 | T36: 0.28727273 | U36: BAT_x000D_ N = 79 | V36: 79 | W36: BAT_x000D_ N = 79 | X36: 36 | Y36: 2006_x000D_ N = 36
A37: SC_06_50053E | B37: 2006 | C37: BAT | D37: 3 | E37: 3 | F37: 3 | G37: 820 | H37: male | I37: present | J37: 2004 | K37: BN | L37: Smolt | M37: BAT | N37: BAT | O37: 491.83192 | P37: 579.09022 | Q37: 0.35 | R37: 275 | S37: 79 | T37: 0.28727273 | U37: BAT_x000D_ N = 79 | V37: 79 | W37: BAT_x000D_ N = 79 | X37: 36 | Y37: 2006_x000D_ N = 36
A38: SC_06_50054E | B38: 2006 | C38: BAT | D38: 3 | E38: 3 | F38: 3 | G38: 510 | H38: unknown | I38: present | J38: 2004 | K38: BN | L38: Smolt | M38: BAT | N38: BAT | O38: 549.74748 | P38: 641.56134 | Q38: 0.22 | R38: 275 | S38: 79 | T38: 0.28727273 | U38: BAT_x000D_ N = 79 | V38: 79 | W38: BAT_x000D_ N = 79 | X38: 36 | Y38: 2006_x000D_ N = 36
A39: SC_06_50100E | B39: 2006 | C39: DEE | D39: 3 | E39: 3 | F39: 3 | G39: NA | H39: unknown | I39: present | J39: 2004 | K39: BN | L39: NA | M39: MILDEE | N39: MILDEE | O39: NA | P39: 0 | Q39: NA | R39: 275 | S39: 67 | T39: 0.24363636 | U39: MILDEE_x000D_ N = 67 | V39: 67 | W39: MILDEE_x000D_ N = 67 | X39: 36 | Y39: 2006_x000D_ N = 36
A40: SC_06_50101E | B40: 2006 | C40: BAT | D40: 3 | E40: 3 | F40: 3 | G40: NA | H40: female | I40: present | J40: 2004 | K40: BN | L40: Smolt | M40: BAT | N40: BAT | O40: 453.16571 | P40: 579.70389 | Q40: 0.35 | R40: 275 | S40: 79 | T40: 0.28727273 | U40: BAT_x000D_ N = 79 | V40: 79 | W40: BAT_x000D_ N = 79 | X40: 36 | Y40: 2006_x000D_ N = 36
...

Sheet Sheet1
A1: Overlapping sources that we want to prioritize for TE (plus 22 CNH) = BAT, SAC, BUT, MIL, DEE, CNH
A3: Methods:
A4: 40x40
A5: 5um/s
A6: 10Hz
A7: Preablation settings??
A9: Element list:
A10: Mg24
A11: Ca43
A12: Ca44
A13: Mn55
A14: Zn66
... A24: YO10 5NG, York,
